Workbook

Sheet Awaiting Approval (AA)
A1: No | B1: Batch | C1: Issues | D1: Tình trạng | E1: File Link | F1: Ghi chú | G1: Review Finish
A2: 1 | B2: MS_170126_001 | C2: Xuất lại file: LN_25_AA1259 16182.1C -> 16183C 16184A Rerun: LN_25_AA1176 2F dyeblob -> PCR-BD 2F LN_25_AA1198 2F dyeblob -> PCR-BD 2F LN_25_AA1199 2F dyeblob -> PCR-BD 2F LN_25_AA1207 2F dyeblob, 3R nền cao (polyAC) -> PCR-BD 2F, 3F, R389 | D2: Đã phê duyệt | E2: MS_170126_001_P
A3: 2 | B3: MS_190126_003 | C3: Rerun: LN_25_AA1630 3R polyC -> PCR-BD 3F, R389 LN_25_AA1672 3R polyC -> PCR-BD 3F, R389 LN_25_AA1691 3R lỗi định dạng -> PCR-BD 3F, R389 LN_25_AA1703 2F dyeblob, 3R lỗi định dạng, 1R peak shoulder -> PCR-BD 2F, 3F, R389, 1R LN_25_AA1707 3R lỗi định dạng -> PCR-BD 3F, R389 | D3: Đã phê duyệt | E3: MS_190126_003_P | F3: Đã báo lab, lab xác nhận cần chạy lại 3 mẫu lỗi định dạng
A4: 3 | B4: MS_210126_002 | C4: Xuất lại file: LN_25_AA1879 152Y LN_25_AA1847 152Y Rerun: LN_25_AA1839 3R polyC PCR-BD 3F, R389 | D4: Đã phê duyệt | E4: MS_210126_002_X_P | F4: Em cập nhật lại đúng folder rồi ạ
A5: 4 | B5: MS_210126_001 | C5: NTC2 1R có trình tự -> blast ko ra hit Rerun: LN_25_AA1771 3R polyC PCR-BD 3F, R389 LN_25_AA1791 3R nền cao (polyAC) PCR-BD 3F, R389 | D5: Đã phê duyệt | E5: MS_210126_001_Q_P
A6: 5 | B6: MS_210126_004 | C6: Review: LN_25_AA2054 (16193del) fullregion -> 73-340 438-576 16024-16192 16194-16365 Đề xuất chạy lại: LN_25_AA2017 3R polyC PCR-BD 3F, R389 | D6: Đã phê duyệt | E6: MS_210126_004_X_H
A7: 6 | B7: MS_220126_001 | C7: Xuân review: XUẤT LẠI FILE: LN_25_AA2116 -> LN_25_AA2116-73-340 438-573 16024-16365 LN_25_AA2144 16093 C -> Y LN_25_AA2074 352.1C -> 356.1C Hùng review: Xuất lại file: LN_25_AA2106 152Y 234R 16092Y LN_25_AA2136 fullregion -> 73-340 438-573 16024-16365 LN_25_AA2151 343N 345N ->xóa Đề xuất chạy lại: LN_25_AA2100 3R polyC PCR-BD 3F, R389 LN_25_AA2116 3R polyC PCR-BD 3F, R389 LN_25_AA2155 3R polyC PCR-BD 3F, R389 LN_25_AA2160 1R tín hiệu yếu PCR-BD 1R | D7: Đã phê duyệt | E7: MS_220126_001_Q_H
A8: 7 | B8: MS_210126_003 | C8: Xuất lại file: LN_25_AA1892 324C->N Đề xuất chạy lại: LN_25_AA1897 3R fail PCR-BD 3F, R389 LN_25_AA1973 3R polyC PCR-BD 3F | D8: Đã phê duyệt | E8: MS_210126_003_X_H
A9: 8 | B9: MS_260126_001 | C9: NTC1 có trình tự, BLAST không ra trình tự Xuất lại file: LN_25_AA2258 312 C->T Rerun: LN_25_AA2255 3R polyC -> PCR-BD 3F, R389 LN_25_AA2266 3R nền cao (polyAC) -> PCR-BD 3F, R389 LN_25_AA2306 1F dyeblob -> PCR-BD 1F LN_25_AA2333 3R nền cao -> PCR-BD 3F, R389 | D9: Đã phê duyệt | E9: MS_260126_001_Q_P
A10: 9 | B10: MS_220126_002 | C10: XUÂN XUẤT LẠI FILE: LN_25_AA2238 XUẤT NHẦM FILE CỦA LN_25_AA2239 -> XUẤT LẠI ĐÚNG FILE Hùng review: Xuất lại file: LN_25_AA2170 306C -> Y LN_25_AA2226 16093C -> Y LN_25_AA2230 16129G -> R LN_25_AA2249 16189C -> Y Đề xuất chạy lại: LN_25_AA2180 3R POLYC -> PCR-BD 3F | D10: Đã phê duyệt | E10: MS_220126_002_X_H
A11: 10 | B11: MS_260126_003 | C11: Trình tự đầu 1F thấp Xuất lại vùng: LN_25_AA2444 73-340 438-576 16037-16365 LN_25_AA2451 73-340 438-576 16037-16365 LN_25_AA2457 73-340 438-576 16037-16365 LN_25_AA2466 73-340 438-576 16037-16365 LN_25_AA2476 73-340 438-576 16037-16365 LN_25_AA2479 73-340 438-576 16037-16365 LN_25_AA2482 73-340 438-576 16037-16365 LN_25_AA2489 73-340 438-576 16037-16365 LN_25_AA2490 73-340 438-576 16037-16365 LN_25_AA2503 73-340 438-576 16037-16365 LN_25_AA2513 73-340 438-576 16037-16365 Rerun: LN_25_AA2441 3R polyAC PCR-BD 3F, R389 LN_25_AA2495 3R polyC PCR-BD 3F | D11: Đã phê duyệt | E11: MS_260126_003_PX_P
A12: 11 | B12: MS_260126_002 | C12: Xuất lại file: LN_25_AA2376 114 A->C Rerun: LN_25_AA2345 3R ngắn -> PCR-BD 3F, R389 | D12: Đã phê duyệt | E12: MS_260126_002_Q_P
A13: 12 | B13: MS_260126_004 | C13: Xuất lại file: LN_25_AA2560-73-302 318-340 438-576 16024-16365, xuất lại vùng Rerun: LN_25_AA2527 3R polyC -> PCR-BD 3F, R389 LN_25_AA2596 3R nền cao -> PCR-BD 3F, R389 | D13: Đã phê duyệt | E13: MS_260126_004_PT_P
A14: 13 | B14: MS_290126_001 | C14: Xuất lại file: LN_26_AA1079-73-302 322-340 438-576 16024-16365, xuất lại vùng LN_26_AA1056 356.1C LN_26_AA1064 16166DEL | D14: Đã phê duyệt | E14: MS_290126_001_TX_P
A15: 14 | B15: MS_290126_002 | C15: Xuất lại file: LN_26_AA1091-73-340 438-573 16024-16365, xuất lại vùng Rerun: LN_26_AA1143 3R polyC PCR-BD 3F, R389 | D15: Đã phê duyệt | E15: MS_290126_002_Q_P
A16: 15 | B16: Mẫu so sánh liên phòng PYQG | C16: 2 mẫu này vẫn có đầy đủ 3 vùng, chỉ là tín hiệu nó ko đc đẹp 241753 3R ngắn 241754 3R tín hiệu kém | D16: Đã phê duyệt | E16: PYQG
... A31: 30 | B31: MS_040226_001 | C31: Quyên review: Đầu 2F nhiễu LN_26_AA1459 152Y không tin cậy, peakshoulder LN_26_AA1514-73-302 16024-16365 3r nền cao sau polyC -> 3F BD, R389 Xuất lại: LN_26_AA1452 577C ->xóa ngoài vùng Hùng review: Xuất lại file LN_26_AA1459 152Y LN_26_AA1468-79-340 438-576 16024-16365 => 76-340 438-576 16024-16365 LN_26_AA1510 miss 249DEL Đề xuất chạy lại: LN_26_AA1514 3R polyC PCR-BD 3F, R389 | D31: Đã phê duyệt | E31: MS_040226_001_Q_H
A32: 31 | B32: MS_260226_001 | C32: Đầu 2F (73-78) tín hiệu chồng lấn Xuất lại file: LN_26_AA0567 352.1C -> 356.1C LN_26_AA0568 16175R LN_26_AA0606 79-302 316-340 438-576 16024-16365, xuất lại vùng Xuất lại vùng (79-340 438-576 16024-16365): LN_26_AA0554 LN_26_AA0559 16175R LN_26_AA0577 LN_26_AA0590 LN_26_AA0621 Rerun: LN_26_AA0560 3R polyC PCR-BD 3F, R389 | D32: Chờ review 2 | E32: MS_260226_001_PT_P | F32: Đã viết báo cáo trên LIMS 2
A33: 32 | B33: MS_070226_002 | C33: Xuất lại file: LN_26_AA2172 xóa 226N 227N LN_26_AA2180 79-340 438-576 16024-16365 => fullregion LN_26_AA2192 76-340 ... -> 79-340 ... LN_26_AA2195 fullregion => 79-340 438-576 16024-16365 LN_26_AA2199 227A -> R LN_26_AA2208 79-340 438-576 16024-16365 => 79-340 438-576 16024-16353 LN_26_AA2218 xóa 573.1 .2 .3 .4; miss 16192Y Đề xuất chạy lại: LN_26_AA2178 3R polyAC PCR-BD 3F, R389 LN_26_AA2187 3R polyC PCR-BD 3F | D33: Đã phê duyệt | E33: MS_070226_002_QX_H
A34: 33 | B34: MS_100226_002 | C34: XUÂN XUẤT LẠI FILE: LN_26_AA2405 16311C -> Y Hùng review: Đầu 2F tín hiệu chồng lấn Đầu 1F tín hiệu kém Đề xuất chạy lại: LN_26_AA2371 3R polyC PCR-BD 3F, R389 LN_26_AA2375 3R polyC PCR-BD 3F, R389 | D34: Đã phê duyệt | E34: MS_100226_002_X_H
A35: 34 | B35: MS_100226_003 | C35: Quyên xuất lại: LN_26_AA2449-79-340 438-573 16024-16365 Review: 1R peak shoulder nhẹ 2F tín hiệu chồng lấn 3R vùng HV2 tín hiệu yếu Xuất lại file: LN_26_AA2439 16190Y LN_26_AA2475 16192Y Đề xuất chạy lại: LN_26_AA2440 3R polyC PCR-BD 3F, R389 LN_26_AA2510 3R polyC PCR-BD 3F, R389 | D35: Đã phê duyệt | E35: MS_100226_003_Q_H
A36: 35 | B36: MS_100226_001 | C36: Xuân xuất lại file: LN_26_AA2273 16361DEL -> 16361G LN_26_AA2313 195T -> Y LN_26_AA2334 16200T -> N; 16203 A->N; 16204 A->N; 16205 G->N LN_26_AA2316 16309G -> R xuất lại vùng: LN_26_AA2329-79-340 438-576 16024-16365 Hùng xuất lại file: AA2269 79-340 438-576 16024-16365 -> 79-340 438-455 464-576 16024-16365 AA2285 79-340 438-576 16024-16365 -> 79-302 438-522 526-576 16024-16365 AA2287 16175 G -> R AA2332 16301Y -> C Đề xuất chạy lại: LN_26_AA2276 3R polyC PCR-BD 3F, R389 LN_26_AA2316 3R polyAC PCR-BD 3F, R389 LN_26_AA2333 1F dyeblob, 16149W? PCR-BD 1F LN_26_AA2334 1R dyeblob PCR-BD 1R | D36: Đã phê duyệt | E36: MS_100226_001_QX_H
A37: 36 | B37: MS_100226_004 | C37: Thủy xuất lại file LN_26_AA2545 459del Hùng review: Xuất lại file: AA2566 16249Y, 79-340 438-576 16024-16365 AA2607 xóa 73G Đề xuất chạy lại: LN_26_AA2556 1R dyeblob PCR-BD 1R LN_26_AA2588 3R polyAC PCR-BD 3F, R389 LN_26_AA2602 16189Y? rePCR -> PCR-BD 1F, 1R | D37: Đã phê duyệt | E37: MS_100226_004_T_H
A38: 37 | B38: MS_250226_001 | C38: Quyên xuất lại: LN_26_AA2611 16093Y LN_26_AA2643 16361DEL ->G Hùng review: Đầu 2F tín hiệu chồng lấn 3R nhiễu nền nhẹ xuất lại file: AA2624 fullregion => 79-340 438-576 16024-16365 AA2650 16182M AA2681 fullregion => 79-340 438-576 16038-16365 Đề xuất chạy lại: LN_26_AA2698 3R polyC PCR-BD 3F, R389 | D38: Đã phê duyệt | E38: MS_250226_001_Q_H
A39: 38 | B39: MS_030326_003 | C39: Xuân xuất lại vùng: LN_26_AA0641-73-340 438-573 16024-16365 -> LN_26_AA0641-73-340 438-560 16024-16365 Hùng review: 1F trước 16084 có tín hiệu nền Đầu 2F một số mẫu tín hiệu chồng lấn xuất lại file: LN_26_AA0718-79-340 438-576 16024-16365 => full region Đề xuất chạy lại: LN_26_AA0641 3R fail PCR-BD 3R LN_26_AA0644 1F nền cao, 3R nền cao trước AC repeat PCR-BD 1F, 3F | D39: Đã phê duyệt | E39: MS_030326_003_X_H
A40: 39 | B40: MS_030326_004 | C40: Thủy xuất lại file LN_26_AA0760 302.1C -> 309.1C Đề xuất chạy lại: LN_26_AA0798 16104M? rePCR --> PCR-BD 1F LN_26_AA0799 73W? PCR-BD R285a | D40: Đã phê duyệt | E40: MS_030326_004_T_H
A41: 40 | B41: MS_250226_002 | C41: Xuân QC: Xuất lại file: LN_26_AA2718 522DEL -> 524DEL Phương review: Đề xuất chạy lại: LN_26_AA2721 3R dyeblob PCR-BD 3F LN_26_AA2728 3R nền cao (polyAC) PCR-BD 3F, R389 | D41: Đã phê duyệt | E41: MS_250226_002_X_P
A42: 41 | B42: MS_280226_004 | C42: Quyên xuất lại vùng: LN_26_AA0322-79-340 438-576 16024-16365 -> -79-302 315-340 438-576 16024-16365 Hùng review: Xuất lại file: LN_26_AA0312 fullregion -> 79-340 438-576 16024-16365 LN_26_AA0322-79-302 315-340.... -> 79-302 316-340 Đề xuất chạy lại: LN_26_AA0326 3R polyC PCR-BD 3F, R389 LN_26_AA0354 3R polyC PCR-BD 3F, R389 | D42: Đã phê duyệt | E42: MS_280226_004_Q_H
A43: 42 | B43: MS_250226_004 | C43: LN_26_AA2885 1F peak shoulder LN_26_AA2938 1F dyeblob nhẹ, 1R peak shoulder Xuất lại file: LN_26_AA2919 full region -> 79-340 438-576 16024-16365 Đề xuất rerun: LN_26_AA2891 2F peak shoulder PCR-BD 2F LN_26_AA2946 1F dyeblob PCR-BD 1F LN_26_AA2953 73A?, 1F dyeblob PCR-BD R285a, 1F | D43: Đã phê duyệt | E43: MS_250226_004_X_P
A44: 43 | B44: MS_280226_001 | C44: Thủy xuất lại file: LN_26_AA0049 16189DEL -> 16193DEL LN_26_AA0065 16189DEL -> 16193DEL LN_26_AA0074 16189DEL -> 16193DEL Hùng xuất lại file: LN_26_AA0066 fullregion -> 79-340 438-576 16024-16365 LN_26_AA0078 16131Y Đề xuất chạy lại: LN_26_AA0071 1F, 1R nhiễm mẫu mức thấp rePCR --> PCR-BD 1F, 1R LN_26_AA0081 3R polyC PCR-BD 3F, R389 | D44: Đã phê duyệt | E44: MS_280226_001_T_H
... A50: 49 | B50: MS_030326_002 | C50: Thủy review Xuất lại file LN_26_AA0497-76-340 438-576 16024-16365 Đề xuất chạy lại: LN_26_AA0533 3R nền sau polyC => PCR-BD 3F, R389 Phương review: Xuất lại: full region -> 79-340 438-576 16024-16365 LN_26_AA0452 LN_26_AA0459 LN_26_AA0460 LN_26_AA0462 LN_26_AA0463 LN_26_AA0466 LN_26_AA0468 LN_26_AA0470 LN_26_AA0472 LN_26_AA0477 LN_26_AA0478 LN_26_AA0495 LN_26_AA0497 LN_26_AA0502 LN_26_AA0518 LN_26_AA0519 LN_26_AA0523 LN_26_AA0527 LN_26_AA0529 LN_26_AA0534 LN_26_AA0535 LN_26_AA0536 LN_26_AA0537 LN_26_AA0538 LN_26_AA0540 Xuất lại: 76-340, 438-576, 16024-16365 -> 79-340, 438-576, 16024-16365 LN_26_AA0471 LN_26_AA0473 LN_26_AA0474 LN_26_AA0476 LN_26_AA0479 LN_26_AA0481 LN_26_AA0482 16129R LN_26_AA0483 LN_26_AA0486 LN_26_AA0488 LN_26_AA0490 LN_26_AA0491 LN_26_AA0493 LN_26_AA0494 LN_26_AA0500 LN_26_AA0501 LN_26_AA0504 LN_26_AA0505 LN_26_AA0506 LN_26_AA0507 LN_26_AA0508 LN_26_AA0510 LN_26_AA0511 LN_26_AA0513 LN_26_AA0514 LN_26_AA0515 LN_26_AA0520 LN_26_AA0521 LN_26_AA0525 LN_26_AA0528 LN_26_AA0531 LN_26_AA0532 Đề xuất rerun: LN_26_AA0461 16292Y? PCR-BD 1R LN_26_AA0501 3R dyeblob PCR-BD 3F LN_26_AA0506 3R nền cao PCR-BD 3F, R389 LN_26_AA0509 3R nền cao + dye blob PCR-BD 3F LN_26_AA0512 16375Y? PCR-BD 1R LN_26_AA0533 3R polyC PCR-BD 3F, R389 | D50: Đã phê duyệt | E50: MS_030326_002_T_P
A51: 50 | B51: MS_060326_002_V002 | C51: Xuất lại file: LN_26_AA3089 miss 16183C 16184A LN_26_AA3091 fullregion => 79-340 438-576 16024-16365 LN_26_AA3112 146Y LN_26_AA3136 16182C => 16182A Đề xuất chạy lại: LN_26_AA3078 3R polyC PCR-BD 3F LN_26_AA3084 3R peak shoulder PCR-BD 3F LN_26_AA3106 Tín hiệu phức tạp Chạy lại từ bước tách -> PCR-BD 1F, 1R, 2F, 3R | D51: Đã phê duyệt | E51: MS_060326_002_V002_T_H | G51: =INDEX('From Batch 20'!K:K, MATCH(B51, 'From Batch 20'!E:E, 0)) -> 46097.659
A52: 51 | B52: MS_060326_001_V001 | C52: Đầu 2F chồng lấn 3R vùng HV2 tín hiệu yếu Đề xuất chạy lại: LN_26_AA2998 2F ngắn PCR-BD 2F LN_26_AA3003 2F dye blob PCR-BD 2F | D52: Đã phê duyệt | E52: MS_060326_001_V001_Q_H | G52: =INDEX('From Batch 20'!K:K, MATCH(B52, 'From Batch 20'!E:E, 0)) -> 46098.384
A53: 52 | B53: MS_280226_002 | C53: Phương review: LN_26_AA0093 LHP tại polyC HVI (16184-16193) Xuất lại file: LN_26_AA0151 574C -> 573.1C 573.2C (nền cao do LHP tại 567-573) LN_26_AA0136 3R nền cao (AC repeat) Đề xuất rerun: LN_26_AA0137 1R tín hiệu không rõ ràng PCR-BD 1R LN_26_AA0152 1R tín hiệu không rõ ràng PCR-BD 1R LN_26_AA0172 73A?, 3R ngắn PCR-BD R285a, 3F, R389 LN_26_AA0179 73A? PCR-BD R285a | D53: Đã phê duyệt | E53: MS_280226_002_X_P | G53: =INDEX('From Batch 20'!K:K, MATCH(B53, 'From Batch 20'!E:E, 0)) -> #N/A
A54: 53 | B54: MS_090326_001_V004 | C54: Xuất lại file: 26_AA3347 16291Y 26_AA3402 16162DEL -> 16166DEL 26_AA3393 311Y Đề xuất chạy lại: LN_26_AA3378 3R polyC PCR-BD 3F, R389 LN_26_AA3410 3R polyC PCR-BD 3F, R389 | D54: Đã phê duyệt | E54: MS_090326_001_V004_T_H | G54: =INDEX('From Batch 20'!K:K, MATCH(B54, 'From Batch 20'!E:E, 0)) -> 46098.491
A55: 54 | B55: MS_100326_001_V008 | C55: NTC1 3R có trình tự, Blast không ra trình tự Đề xuất rerun: LN_26_AA3779-73-302 316-340 438-576 16024-16365 Poly C HVII tín hiệu không rõ ràng (310N?), tồn tại LHP tại polyC HVI gây khó xác định hetero -> tách lại | D55: Đã phê duyệt | E55: MS_100326_001_V008_P_P | G55: =INDEX('From Batch 20'!K:K, MATCH(B55, 'From Batch 20'!E:E, 0)) -> 46098.729
A56: 55 | B56: MS_090326_003_V006 | C56: NTC1 1R có trình tự- BLAST không có Quyên xuất lại: LN_26_AA3571-79-340 438-573 16024-16365 Hùng xuất lại file: LN_26_AA3571-79-340 438-573 16024-16365 => 79-340 438-566 16024-16365 | D56: Đã phê duyệt | E56: MS_090326_003_V006_Q_H | G56: =INDEX('From Batch 20'!K:K, MATCH(B56, 'From Batch 20'!E:E, 0)) -> 46099.377
A57: 56 | B57: MS_090326_004_V007 | C57: Một số trình tự 3R nhiễu: LN_26_AA3605, LN_26_AA3632, LN_26_AA3643 | D57: Đã phê duyệt | E57: MS_090326_004_V007_T_H | G57: =INDEX('From Batch 20'!K:K, MATCH(B57, 'From Batch 20'!E:E, 0)) -> 46099.43
A58: 57 | B58: MS_090326_002_V005 | C58: Phương review: LN_26_AA3446 3R nền cao (AC repeat) Xuất lại file: LN_26_AA3432 16189Y LN_26_AA3454 456DEL -> 459DEL Xuất lại vùng: 79-340 438-576 16024-16365 -> 79-340 438-573 16024-16365 LN_26_AA3474 Xuất lại vùng: Full region -> 79-340 438-576 16024-16365 LN_26_AA3449 LN_26_AA3495 LN_26_AA3506 Xuất lại vùng: 79-340 438-576 16024-16365 -> full region LN_26_AA3480 LN_26_AA3481 LN_26_AA3494 LN_26_AA3496 Đề xuất rerun: LN_26_AA3482 3R nền cao (polyAC) PCR-BD 3F | D58: Đã phê duyệt | E58: MS_090326_002_V005_X_P | G58: =INDEX('From Batch 20'!K:K, MATCH(B58, 'From Batch 20'!E:E, 0)) -> 46099.485
A59: 58 | B59: MS_100326_003_V009 | C59: Xuân QC: Xuất lại vùng: LN_26_AA3929 FULL REGION -> LN_26_AA3929-79-340 438-576 16024-16365 LN_26_AA3939 FULL REGION -> LN_26_AA3939-79-340 438-576 16024-16365 Phương review: Xuất lại file: LN_26_AA3873 16189Y LN_26_AA3894 full region -> 79-340 438-576 16024-16365 Đề xuất rerun: LN_26_AA3930 73A? PCR-BD R285a LN_26_AA3950 3R polyC PCR-BD 3F, R389 | D59: Đã phê duyệt | E59: MS_100326_003_V009_X_P | G59: =INDEX('From Batch 20'!K:K, MATCH(B59, 'From Batch 20'!E:E, 0)) -> 46099.626
...

Sheet From Batch 20
A1: Batch mtDNA | B1: Sequence Released Date | C1: No. of Samples | D1: Analysis Code | E1: Batch mtDNA-Analysis Code | F1: Analyst(s) | G1: Batch Receive Time | H1: No. of Samples Analysed by Sequencher | I1: Sequencher Analysis Transfer Time | J1: 1st Review | K1: Review Finish | L1: 2nd Review | M1: No. of Samples Passed by Sequencher Analysis (1st run) | N1: No. of Samples Passed by Sequencher Analysis (rerun) | O1: No. of Samples Passed by Sequencher Analysis Transfered to Next Stage | P1: Sequencher Analysis Results from Lab to Sciences Date | Q1: Sequencher Analysis (Batches) | R1: Analyst(s) | S1: Sequencher vs Pipeline Comparison | T1: Regenerated Reports by the Science Team | U1: Regenerated Reports Realeased Date | V1: Numbers of Reports Released | W1: Reports Check by Nam | X1: Final Reports | Y1: Note1 | Z1: Done | AA1: Run1 Analysis Results Released Date | AB1: Rerun Analysis Results Released Date | AC1: Note1 | AD1: Note 2 | AE1: Note 2
A2: Sum of samples | B2: - | C2: =SUMIF(A4:A99998,"<>",C4:C99998) -> 47218 | D2: - | E2: - | F2: - | G2: - | H2: =SUM(H4:H1048559) -> 47202 | I2: - | J2: =SUMIF(J4:J99998,"<>",H4:H99998) -> 46752 | K2: - | L2: =SUMIF(L4:L99998,"<>",H4:H99998) -> 46572 | M2: =SUM(M4:M1048559) -> 44386 | N2: =SUM(N4:N1048559) -> 581 | O2: =SUM(O4:O1048559) -> 6701 | Q2: =COUNTIF(Q4:Q1048576,"Done") -> 9 | R2: - | S2: - | T2: - | W2: - | X2: =SUM(X4:X1048576) -> 2069 | Z2: =SUM(M2:N2) -> 44967 | AF2: HY
A3: Remaining samples | B3: - | D3: - | E3: - | F3: - | G3: - | H3: =C2-H2 -> 16 | I3: - | J3: =C2-J2 -> 466 | K3: - | L3: =C2-L2 -> 646 | O3: =C2-O2 -> 40517 | Q3: - | R3: - | S3: - | T3: - | W3: - | X3: - | Z3: =C2-Z2 -> 2251
A4: 20 | B4: 45735 | C4: 91 | F4: - | G4: - | H4: 91 | I4: - | J4: - | K4: - | L4: - | M4: 91 | N4: =IF(M4=C4,"-","") -> - | O4: 91 | P4: 250321 | Q4: Done | R4: N (Ms) | T4: Released | U4: 250321 | V4: 91 | W4: Done | X4: 91 | Z4: =IF(SUM(M4,N4)=C4,"DONE"," ") -> DONE | AC4: Tiền Giang
A5: 21 | B5: 45745 | C5: 92 | F5: - | G5: - | H5: 92 | I5: - | J5: - | K5: - | L5: - | M5: 88 | N5: 4 | O5: 88 | P5: 250401 | R5: N (Ms) | T5: Released | U5: 250402 | V5: 88 | W5: Done | X5: 88 | Y5: 4 mẫu lab chạy lại từ PCR | Z5: =IF(SUM(M5,N5)=C5,"DONE"," ") -> DONE | AA5: 45848 | AC5: Nghệ An - Hà Tĩnh
A6: 22 | B6: 45749 | C6: 92 | F6: - | G6: - | H6: 92 | I6: - | J6: - | K6: - | L6: - | M6: 86 | N6: 4 | O6: 86 | P6: 250404 | R6: N (Ms) | T6: Released | U6: 250404 | V6: 86 | W6: Done | X6: 86 | Y6: 4 mẫu lab chạy lại PCR-bigdye 3F, 2 mẫu chạy lại từ tách chiết | Z6: DONE | AA6: 45848 | AC6: Nghệ An - Hà Tĩnh (2 mẫu đã chạy xác minh, trả ở batch 28)
A7: 23 | B7: 45751 | C7: 92 | F7: - | G7: - | H7: 92 | I7: - | J7: - | K7: - | L7: - | M7: 92 | N7: =IF(M7=C7,"-","") -> - | O7: 92 | P7: 250408 | Q7: Done | R7: N (Ms) | T7: Released | U7: 250408 | V7: 92 | W7: Done | X7: 92 | Z7: =IF(SUM(M7,N7)=C7,"DONE"," ") -> DONE | AC7: Nghệ An - Hà Tĩnh
A8: 24 | B8: 45755 | C8: 92 | F8: - | G8: - | H8: 92 | I8: - | J8: - | K8: - | L8: - | M8: 92 | N8: =IF(M8=C8,"-","") -> - | O8: 92 | P8: 250410 | Q8: Done | R8: N (Ms) | T8: Released | U8: 250410 | V8: 92 | W8: Done | X8: 92 | Z8: =IF(SUM(M8,N8)=C8,"DONE"," ") -> DONE | AC8: Nghệ An - Hà Tĩnh
A9: 25 | B9: 45756 | C9: 92 | F9: - | G9: - | H9: 92 | I9: - | J9: - | K9: - | L9: - | M9: 92 | N9: =IF(M9=C9,"-","") -> - | O9: 92 | P9: 250411 | Q9: Done | R9: N (Ms) | T9: Released | U9: 250416 | V9: 92 | W9: Done | X9: 92 | Z9: =IF(SUM(M9,N9)=C9,"DONE"," ") -> DONE | AC9: Nghệ An - Hà Tĩnh
A10: 26 | B10: 45758 | C10: 92 | F10: - | G10: - | H10: 92 | I10: - | J10: - | K10: - | L10: - | M10: 91 | N10: 1 | O10: 91 | P10: 250418 | R10: N (Ms) | T10: Released | U10: 250421 | V10: 91 | W10: Done | X10: 91 | Y10: 253034: yc chạy BS HV3F | Z10: =IF(SUM(M10,N10)=C10,"DONE"," ") -> DONE | AA10: 45848 | AC10: Nghệ An - Hà Tĩnh
A11: 27 | B11: 45757 | C11: 92 | F11: - | G11: - | H11: 92 | I11: - | J11: - | K11: - | L11: - | M11: 92 | N11: =IF(M11=C11,"-","") -> - | O11: 92 | P11: 250416 | Q11: Done | R11: N (Ms) | T11: Released | U11: 250421 | V11: 92 | W11: Done | X11: 92 | Z11: =IF(SUM(M11,N11)=C11,"DONE"," ") -> DONE | AC11: Nghệ An - Hà Tĩnh
A12: 28 | B12: 45763 | C12: 92 | F12: - | G12: - | H12: 92 | I12: - | J12: - | K12: - | L12: - | M12: 84 | N12: 8 | O12: 84 | P12: 250425 | R12: T, Q, N (Ms) | T12: Released | U12: 250428 | V12: 84 | W12: Done | X12: 84 | Y12: 2 mẫu 252251, 252278 (mt22, nhóm mẫu Nghệ An - Hà Tĩnh) đã được chạy lại từ tách chiết và xác nhận đúng KQ. 8 mẫu yc chạy BS | Z12: =IF(SUM(M12,N12)=C12,"DONE"," ") -> DONE | AA12: 45828 | AC12: Hà Nam + 2 Nghệ An - Hà Tĩnh
A13: 29 | B13: 45764 | C13: 92 | F13: - | G13: - | H13: 92 | I13: - | J13: - | K13: - | L13: - | M13: 92 | N13: =IF(M13=C13,"-","") -> - | O13: 92 | P13: 250421 | Q13: Done | R13: N (Ms) | T13: Released | U13: 250421 | V13: 92 | W13: Done | X13: 92 | Y13: lưu ý 253888 có del ở 16166. 4 mẫu yc chạy BS | Z13: =IF(SUM(M13,N13)=C13,"DONE"," ") -> DONE | AC13: Hà Nam (1 mẫu thuộc ca Đức Cơ)
A14: 30 | B14: 45705 | C14: 92 | F14: - | G14: - | H14: 92 | I14: - | J14: - | K14: - | L14: - | M14: 88 | N14: 4 | O14: 88 | P14: 250424 | R14: T, N (Ms) | T14: Released | U14: 250428 | V14: 88 | W14: Done | X14: 88 | Y14: 4 mẫu chạy BS | Z14: =IF(SUM(M14,N14)=C14,"DONE"," ") -> DONE | AA14: 45828 | AC14: Hà Nam (1 mẫu thuộc ca Đức Cơ)
A15: 31 | B15: 45768 | C15: 92 | F15: - | G15: - | H15: 92 | I15: - | J15: - | K15: - | L15: - | M15: 89 | N15: 3 | O15: 89 | P15: 250428 | R15: N (Ms) | T15: Released | U15: 250428 | V15: 89 | W15: Done | X15: 89 | Y15: 3 mẫu chạy BS | Z15: =IF(SUM(M15,N15)=C15,"DONE"," ") -> DONE | AA15: 45828 | AC15: Hà Nam
A16: 32 | B16: 45770 | C16: 92 | F16: - | G16: - | H16: 92 | I16: - | J16: - | K16: - | L16: - | M16: 92 | N16: =IF(M16=C16,"-","") -> - | O16: 92 | P16: 250428 | Q16: Done | R16: T, N (Ms) | T16: Released | U16: 250428 | V16: 92 | W16: Done | X16: 92 | Z16: =IF(SUM(M16,N16)=C16,"DONE"," ") -> DONE | AC16: Hà Nam
A17: 33 | B17: 45771 | C17: 92 | F17: - | G17: - | H17: 92 | I17: - | J17: - | K17: - | L17: - | M17: 92 | N17: =IF(M17=C17,"-","") -> - | O17: 92 | P17: 250505 | Q17: Done | R17: Q, N (Ms) | T17: Released | U17: 250505 | V17: 92 | W17: Done | X17: 92 | Z17: =IF(SUM(M17,N17)=C17,"DONE"," ") -> DONE | AC17: Hà Nam
A18: 34 | B18: 45773 | C18: 92 | F18: - | G18: - | H18: 92 | I18: - | J18: - | K18: - | L18: - | M18: 90 | N18: 2 | O18: 90 | P18: 250429 | R18: T, N (Ms) | T18: Released | U18: 250429 | V18: 90 | W18: Done | X18: 90 | Y18: 2 mẫu chạy BS | Z18: =IF(SUM(M18,N18)=C18,"DONE"," ") -> DONE | AA18: 45828 | AC18: Hà Nam
A19: 35 | B19: 45773 | C19: 92 | F19: - | G19: - | H19: 92 | I19: - | J19: - | K19: - | L19: - | M19: 92 | N19: =IF(M19=C19,"-","") -> - | O19: 92 | P19: 250505 | Q19: Done | R19: T, N (Ms) | T19: Released | U19: 250506 | V19: 92 | W19: Done | X19: 92 | Z19: =IF(SUM(M19,N19)=C19,"DONE"," ") -> DONE | AC19: Hà Nam
A20: 36 | B20: 45774 | C20: 92 | F20: - | G20: - | H20: 92 | I20: - | J20: - | K20: - | L20: - | M20: 89 | N20: 3 | O20: 89 | P20: 250505 | R20: T, N (Ms) | T20: Released | U20: 250505 | V20: 89 | W20: Done | X20: 89 | Y20: 3 mẫu chạy BS | Z20: =IF(SUM(M20,N20)=C20,"DONE"," ") -> DONE | AA20: 45828 | AC20: Hà Nam
A21: 37 | B21: 45775 | C21: 90 | F21: - | G21: - | H21: 90 | I21: - | J21: - | K21: - | L21: - | M21: 87 | N21: 3 | O21: 87 | P21: 250505 | R21: N (Ms) | T21: Released | U21: 250506 | V21: 87 | W21: Done | X21: 87 | Z21: =IF(SUM(M21,N21)=C21,"DONE"," ") -> DONE | AA21: 45828 | AC21: Hà Nam
A22: 38 | B22: 45776 | C22: 92 | F22: - | G22: - | H22: 92 | I22: - | J22: - | K22: - | L22: - | M22: 91 | N22: 1 | O22: 91 | P22: 250505 | R22: T, N (Ms) | T22: Released | U22: 250506 | V22: 91 | W22: Done | X22: 91 | Y22: 1 mẫu chạy BS | Z22: =IF(SUM(M22,N22)=C22,"DONE"," ") -> DONE | AA22: 45828 | AC22: Hà Nam
A23: 40 | B23: 45783 | C23: 91 | F23: - | G23: - | H23: 91 | I23: - | J23: - | K23: - | L23: - | M23: 89 | N23: 1 | O23: 89 | P23: 250507 | T23: Released | U23: 250508 | V23: 89 | W23: Done | X23: 89 | Y23: 1 mẫu tách lại, 1 mẫu chạy BS | Z23: DONE | AA23: 45828 | AC23: Hà Nam (lặp 1 mẫu chạy lại từ bước tách, trả KQ ở batch mt52)
A24: 39 | B24: 45785 | C24: 92 | F24: - | G24: - | H24: 92 | I24: - | J24: - | K24: - | L24: - | M24: 91 | N24: 0 | O24: 91 | P24: 250509 | T24: Released | U24: 250509 | V24: 91 | W24: Done | X24: 91 | Y24: 1 mẫu tách lại | Z24: DONE | AC24: Hà Nam (lặp 1 mẫu chạy lại từ bước tách, trả KQ ở batch mt52)
A25: 41 | B25: 45785 | C25: 92 | F25: - | G25: - | H25: 92 | I25: - | J25: - | K25: - | L25: - | M25: 88 | N25: 4 | O25: 88 | P25: 250509 | T25: Released | U25: 250512 | V25: 88 | W25: Done | X25: 88 | Y25: 4 mẫu chạy lại | Z25: =IF(SUM(M25,N25)=C25,"DONE"," ") -> DONE | AA25: 45828 | AC25: Hà Nam
A26: 42 | B26: 45786 | C26: 92 | F26: - | G26: - | H26: 92 | I26: - | J26: - | K26: - | L26: - | M26: 91 | N26: 1 | O26: 91 | P26: 250512 | T26: Released | U26: 250513 | V26: 91 | W26: Done | X26: 91 | Z26: =IF(SUM(M26,N26)=C26,"DONE"," ") -> DONE | AA26: 45828 | AC26: Hà Nam
A27: 43 | B27: 45787 | C27: 92 | F27: - | G27: - | H27: 92 | I27: - | J27: - | K27: - | L27: - | M27: 90 | N27: 2 | O27: 90 | P27: 250518 | U27: 45796 | V27: 90 | Z27: =IF(SUM(M27,N27)=C27,"DONE"," ") -> DONE | AC27: Hà Nam
A28: 44 | B28: 45788 | C28: 92 | F28: - | G28: - | H28: 92 | I28: - | J28: - | K28: - | L28: - | M28: 89 | N28: 3 | O28: 89 | P28: 250513 | T28: Released | U28: 250516 | V28: 89 | Z28: =IF(SUM(M28,N28)=C28,"DONE"," ") -> DONE | AA28: 45828 | AC28: Hà Nam
A29: 45 | B29: 45789 | C29: 92 | F29: - | G29: - | H29: 92 | I29: - | J29: - | K29: - | L29: - | M29: 86 | N29: 6 | O29: 86 | P29: 250515 | T29: Released | U29: 250516 | V29: 86 | Z29: =IF(SUM(M29,N29)=C29,"DONE"," ") -> DONE | AA29: 45828 | AC29: Hà Nam
A30: 46 | B30: 45790 | C30: 92 | F30: - | G30: - | H30: 92 | I30: - | J30: - | K30: - | L30: - | M30: 89 | N30: 3 | O30: 89 | P30: 250515 | T30: Released | U30: 250516 | V30: 89 | Z30: =IF(SUM(M30,N30)=C30,"DONE"," ") -> DONE | AA30: 45792 | AB30: 45844 | AC30: Hà Nam
A31: 47 | B31: 45791 | C31: 92 | F31: - | G31: - | H31: 92 | I31: - | J31: - | K31: - | L31: - | M31: 84 | N31: 8 | O31: 84 | P31: 250517 | U31: 45796 | V31: 84 | Z31: =IF(SUM(M31,N31)=C31,"DONE"," ") -> DONE | AC31: Hà Nam
A32: 48 | B32: 45793 | C32: 92 | F32: - | G32: - | H32: 92 | I32: - | J32: - | K32: - | L32: - | M32: 86 | N32: 6 | O32: 86 | P32: 250518 | U32: 45796 | V32: 86 | Z32: =IF(SUM(M32,N32)=C32,"DONE"," ") -> DONE | AC32: Hà Nam
A33: 49 | B33: 45796 | C33: 92 | F33: - | G33: - | H33: 92 | I33: - | J33: - | K33: - | L33: - | M33: 90 | N33: 2 | O33: 90 | P33: 45797 | Z33: =IF(SUM(M33,N33)=C33,"DONE"," ") -> DONE | AC33: Hà Nam
A34: 50 | B34: 45796 | C34: 92 | F34: - | G34: - | H34: 92 | I34: - | J34: - | K34: - | L34: - | M34: 92 | N34: =IF(M34=C34,"-","") -> - | O34: 92 | P34: 45797 | Z34: =IF(SUM(M34,N34)=C34,"DONE"," ") -> DONE | AA34: 45797 | AC34: Hà Nam
A35: 51 | B35: 45796 | C35: 92 | F35: - | G35: - | H35: 92 | I35: - | J35: - | K35: - | L35: - | M35: 90 | N35: 2 | O35: 90 | P35: 45799 | Z35: =IF(SUM(M35,N35)=C35,"DONE"," ") -> DONE | AA35: 45799 | AB35: 45848 | AC35: Hà Nam
A36: 52 | B36: 45796 | C36: 92 | F36: - | G36: - | H36: 92 | I36: - | J36: - | K36: - | L36: - | M36: 91 | N36: 1 | O36: 91 | P36: 45798 | Z36: =IF(SUM(M36,N36)=C36,"DONE"," ") -> DONE | AB36: 45847 | AC36: Hà Nam (1 mẫu thuộc ca Đức Cơ)
A37: 54 | B37: 45797 | C37: 92 | F37: - | G37: - | H37: 92 | I37: - | J37: - | K37: - | L37: - | M37: 92 | N37: =IF(M37=C37,"-","") -> - | O37: 92 | P37: 45799 | Z37: =IF(SUM(M37,N37)=C37,"DONE"," ") -> DONE | AA37: 45799 | AC37: Hà Nam
A38: 53 | B38: 45798 | C38: 92 | F38: - | G38: - | H38: 92 | I38: - | J38: - | K38: - | L38: - | M38: 92 | N38: =IF(M38=C38,"-","") -> - | O38: 92 | P38: 45800 | Z38: =IF(SUM(M38,N38)=C38,"DONE"," ") -> DONE | AA38: 45800 | AC38: Hà Nam
A39: 55 | B39: 45798 | C39: 92 | F39: - | G39: - | H39: 92 | I39: - | J39: - | K39: - | L39: - | M39: 91 | N39: 1 | O39: 91 | P39: 45800 | Z39: =IF(SUM(M39,N39)=C39,"DONE"," ") -> DONE | AA39: 45800 | AB39: 45844 | AC39: Hà Nam
A40: 56 | B40: 45799 | C40: 92 | F40: - | G40: - | H40: 92 | I40: - | J40: - | K40: - | L40: - | M40: 92 | N40: =IF(M40=C40,"-","") -> - | O40: 92 | P40: 45803 | Z40: =IF(SUM(M40,N40)=C40,"DONE"," ") -> DONE | AA40: 45799 | AC40: Hà Nam
...

Sheet SL KQ theo ngày
A1: Nội dung | B1: 2024 | C1: Từ 01/04/2025 tới 08/05/2025 | D1: 45905 | E1: 45935 | F1: 45966 | G1: 45996 | H1: 13/05/2025 | I1: 14/05/2025 | J1: 15/05/2025 | K1: 16/05/2025 | L1: 17/05/2025 | M1: 18/05/2025 | N1: 19/05/2025 | O1: 20/05/2025 | P1: 21/05/2025 | Q1: 22/05/2025 | R1: 23/05/2025 | S1: 24/05/2025 | T1: 25/05/2025 | U1: 26/05/2025 | V1: 27/05/2025 | W1: 28/05/2025 | X1: 29/05/2025 | Y1: 30/05/2025 | Z1: 31/05/2025 | AA1: 45663 | AB1: 45694 | AC1: 45722 | AD1: 45753 | AE1: 45783 | AF1: 45814 | AG1: 45844 | AH1: 45875 | AI1: 45906 | AJ1: 45936 | AK1: 45967 | AL1: 45997 | AM1: 13/06/2025 | AN1: 14/06/2025 | AO1: 15/06/2025 | AP1: 16/06/2025 | AQ1: 17/06/2025 | AR1: 18/06/2025 | AS1: 19/06/2025 | AT1: 20/06/2025 | AU1: 21/06/2025 | AV1: 22/06/2025 | AW1: 23/06/2025 | AX1: 24/06/2025 | AY1: 25/06/2025 | AZ1: 26/06/2025 | BA1: 27/06/2025 | BB1: 28/06/2025 | BC1: 29/06/2025 | BD1: 30/06/2025 | BE1: 45664 | BF1: 45695 | BG1: 45723 | BH1: 45754 | BI1: 45784 | BJ1: 45815 | BK1: 45845 | BL1: 45876 | BM1: 45907 | BN1: 45937 | BO1: 45968 | BP1: 45998 | BQ1: 13/07/2025 | BR1: 14/07/2025 | BS1: 15/07/2025 | BT1: 16/07/2025 | BU1: 17/07/2025 | BV1: 18/07/2025 | BW1: 19/07/2025 | BX1: 20/07/2025 | BY1: 21/07/2025 | BZ1: 22/07/2025 | CA1: 23/07/2025 | CB1: 24/07/2025 | CC1: 25/07/2025 | CD1: 26/07/2025 | CE1: 27/07/2025 | CF1: 28/07/2025 | CG1: 29/07/2025 | CH1: 30/07/2025 | CI1: 31/07/2025 | CJ1: 45665 | CK1: 45696 | CL1: 45724 | CM1: 45755 | CN1: 45785 | CO1: 45816 | CP1: 45846 | CQ1: 45877 | CR1: 45908 | CS1: 45938 | CT1: 45969 | CU1: 45999 | CV1: 13/8/2025 | CW1: 14/08/2025 | CX1: 15/08/2025 | CY1: 16/08/2025 | CZ1: 17/08/2025 | DA1: 18/08/2025 | DB1: 19/08/2025 | DC1: 20/08/2025 | DD1: 21/08/2025 | DE1: 22/08/2025 | DF1: 23/08/2025 | DG1: 24/08/2025 | DH1: 25/08/2025 | DI1: 26/08/2025 | DJ1: 27/08/2025 | DK1: 28/08/2025 | DL1: 29/08/2025 | DM1: 30/08/2025 | DN1: 45666 | DO1: 45697 | DP1: 45725 | DQ1: 45756 | DR1: 45786 | DS1: 45817 | DT1: 45907 | DU1: 45908 | DV1: 45909 | DW1: 45939 | DX1: 45970 | DY1: 46000 | DZ1: 13/09/2025 | EA1: 14/09/2025 | EB1: 15/09/2025 | EC1: 16/09/2025 | ED1: 17/09/2025 | EE1: 18/09/2025 | EF1: 19/09/2025 | EG1: 20/09/2025 | EH1: 21/09/2025 | EI1: 22/09/2025 | EJ1: 23/09/2025 | EK1: 24/09/2025 | EL1: 25/09/2025 | EM1: 26/09/2025 | EN1: 27/09/2025 | EO1: 28/09/2025 | EP1: 29/09/2025 | EQ1: 30/09/2025 | ER1: 45667 | ES1: 45698 | ET1: 45726 | EU1: 45757 | EV1: 45787 | EW1: 45818 | EX1: 45848 | EY1: 45879 | EZ1: 45910 | FA1: 45940 | FB1: 45971 | FC1: 46001 | FD1: 13/10/2025 | FE1: 14/10/2025 | FF1: 15/10/2025 | FG1: 16/10/2025 | FH1: 17/10/2025 | FI1: 18/10/2025 | FJ1: 19/10/2025 | FK1: 20/10/2025 | FL1: 21/10/2025 | FM1: 22/10/2025 | FN1: 23/10/2025 | FO1: 24/10/2025 | FP1: 25/10/2025 | FQ1: 26/10/2025 | FR1: 27/10/2025 | FS1: 28/10/2025 | FT1: 29/10/2025 | FU1: 30/10/2025 | FV1: 31/10/2025 | FW1: 45668 | FX1: 45699 | FY1: 45727 | FZ1: 45758 | GA1: 45788 | GB1: 45819 | GC1: 45849 | GD1: 45880 | GE1: 45911 | GF1: 45941 | GG1: 45972 | GH1: 46002 | GI1: 13/11/2025 | GJ1: 14/11/2025 | GK1: 15/11/2025 | GL1: 16/11/2025 | GM1: 17/11/2025 | GN1: 18/11/2025 | GO1: 19/11/2025 | GP1: 20/11/2025 | GQ1: 21/11/2025 | GR1: 22/11/2025 | GS1: 23/11/2025 | GT1: 24/11/2025 | GU1: 25/11/2025 | GV1: 26/11/2025 | GW1: 27/11/2025 | GX1: 21/11/2025 | GY1: 25/11/2025 | GZ1: 28/11/2025 | HA1: 01/12/2025 | HB1: 02/12/2025 | HC1: 03/12/2025 | HD1: 04/12/2025 | HE1: 05/12/2025 | HF1: 08/12/2025 | HG1: 09/12/2025 | HH1: 10/12/2025 | HI1: 11/12/2025 | HJ1: 12/12/2025 | HK1: 13/12/2025 | HL1: 14/12/2025 | HM1: 15/12/2025 | HN1: 16/12/2025 | HO1: 17/12/2025 | HP1: 18/12/2025 | HQ1: 19/12/2025 | HR1: 22/12/2025 | HS1: 23/12/2025 | HT1: 24/12/2025 | HU1: 25/12/2025 | HV1: 26/12/2025 | HW1: 29/12/2025 | HX1: 30/12/2025 | HY1: 31/12/2025 | HZ1: 5/1/2026 | IA1: 6/1/2026 | IB1: 7/1/2026 | IC1: 8/1/2026 | ID1: 9/1/2026 | IE1: 12/1/2026 | IF1: 13/1/2026 | IG1: 14/1/2026 | IH1: 15/1/2026 | II1: 16/1/2026 | IJ1: 19/1/2026 | IK1: 20/1/2026 | IL1: 21/1/2026 | IM1: 22/1/2026 | IN1: 23/1/2026 | IO1: 24/1/2026 | IP1: 26/1/2025 | IQ1: 27/1/2025 | IR1: 28/1/2025 | IS1: 29/1/2026 | IT1: 30/1/2026 | IU1: 2/2/2026 | IV1: 3/2/2026 | IW1: 46114 | IX1: 46144 | IY1: 46175 | IZ1: 46267 | JA1: 46297 | JB1: 46328 | JC1: 46358 | JD1: 13/2/2026 | JE1: 25/2/2026 | JF1: 26/2/2026 | JG1: 27/2/2026 | JH1: 2/3/2026 | JI1: 3/3/2026 | JJ1: 4/3/2026 | JK1: 5/3/2026 | JL1: 6/3/2026 | JM1: 9/3/2026 | JN1: 10/3/2026 | JO1: 11/3/2026 | JP1: 12/3/2026 | JQ1: 13/3/2026 | JR1: 16/3/2026 | JS1: 17/3/2026 | JT1: 18/3/2026 | JU1: 19/3/2026 | JV1: 20/3/2026 | JW1: 23/3/2026 | JX1: 24/3/2026 | JY1: 25/3/2026 | JZ1: 26/3/2026 | KA1: 27/3/2026 | KB1: 30/3/2026 | KC1: 31/3/2026 | KD1: 1/4/2026 | KE1: 2/4/2026 | KF1: 3/4/2026 | KG1: 5/4/2026 | KH1: 6/4/2026 | KI1: 7/4/2026 | KJ1: 8/4/2026 | KK1: 9/4/2026 | KL1: 10/4/2026
A2: Phân tích mtDNA | B2: 688 | C2: 1652 | D2: 184 | E2: 0 | F2: 0 | G2: 92 | H2: 89 | I2: 86 | J2: 89 | K2: 84 | L2: 0 | M2: 0 | N2: 176 | O2: 182 | P2: 91 | Q2: 182 | R2: 183 | S2: 0 | T2: 183 | U2: 91 | V2: 180 | W2: 92 | X2: 167 | Y2: 179 | Z2: 0 | AA2: 0 | AB2: 90 | AC2: 183 | AD2: 87 | AE2: 182 | AF2: 91 | AG2: 0 | AH2: 0 | AI2: 292 | AJ2: 180 | AK2: 145 | AL2: 174 | AM2: 86 | AN2: 0 | AO2: 338 | AP2: 160 | AQ2: 180 | AR2: 265 | AS2: 162 | AT2: 174 | AU2: 0 | AV2: 429 | AW2: 178 | AX2: 179 | AY2: 193 | AZ2: 175 | BA2: 166 | BB2: 0 | BC2: 0 | BD2: 356 | BE2: 265 | BF2: 86 | BG2: 179 | BH2: 0 | BI2: 0 | BJ2: 120 | BK2: 0 | BL2: 15 | BM2: 39 | BN2: 0 | BO2: 174 | BP2: 0 | BQ2: 0 | BR2: 457 | BS2: 176 | BT2: 266 | BU2: 175 | BV2: 86 | BW2: 0 | BX2: 200 | BY2: 461 | BZ2: 257 | CA2: 432 | CB2: 176 | CC2: 0 | CD2: 0 | CE2: 304 | CF2: 304 | CG2: 88 | CH2: 175 | CI2: 178 | CJ2: 263 | CK2: 0 | CL2: 0 | CM2: 427 | CN2: 350 | CO2: 176 | CP2: 267 | CQ2: 176 | CR2: 0 | CS2: 0 | CT2: 308 | CU2: 172 | CV2: 0 | CW2: 175 | CX2: 0 | CY2: 0 | CZ2: 0 | DA2: 0 | DB2: 174 | DC2: 280 | DD2: 87 | DE2: 259 | DH2: 88 | DI2: 260 | DJ2: 258 | DK2: 261 | DL2: 251 | DP2: 169 | DQ2: 0 | DR2: 345 | DW2: 83 | DX2: 255 | DY2: 88 | EF2: 262 | EI2: 257 | EK2: 84 | EL2: 71 | EM2: 83 | EP2: 83 | EQ2: 256 | ER2: 86 | ES2: 259 | EU2: 0 | EV2: 0 | EW2: 264 | EX2: 0 | EY2: 265 | EZ2: 86 | FA2: 438 | FE2: 263 | FG2: 86 | FH2: 82 | FK2: 261 | FL2: 0 | FM2: 261 | FN2: 0 | FO2: 349 | FS2: 178 | FT2: 265 | FU2: 194 | FV2: 271 | FY2: 100 | FZ2: 262 | GB2: 351 | GC2: 252 | GF2: 258 | GG2: 172 | GH2: 172 | GI2: 176 | GJ2: 179 | GK2: 0 | GL2: 0 | GM2: 0 | GN2: 350 | GO2: 260 | GP2: 89 | GQ2: 348 | GR2: 0 | GS2: 0 | GT2: 172 | GU2: 177 | GV2: 0 | GW2: 0 | GZ2: 446 | HA2: 262 | HB2: 177 | HC2: 0 | HD2: 441 | HE2: 352 | HF2: 177 | HG2: 261 | HH2: 0 | HI2: 266 | HJ2: 179 | HK2: 0 | HL2: 0 | HM2: 255 | HN2: 176 | HO2: 264 | HP2: 263 | HQ2: 268 | HR2: 265 | HS2: 262 | HT2: 0 | HU2: 84 | HV2: 261 | HW2: 346 | HX2: 258 | HY2: 266 | HZ2: 0 | IA2: 0 | IB2: 79 | IC2: 168 | ID2: 174 | IE2: 174 | IF2: 267 | IG2: 0 | IH2: 230 | II2: 261 | IJ2: 170 | IK2: 263 | IL2: 258 | IM2: 265 | IN2: 177 | IO2: 87 | IP2: 0 | IQ2: 0 | IR2: 249 | IS2: 263 | IT2: 312 | IU2: 89 | IV2: 265 | IW2: 179 | IX2: 0 | IY2: 171 | IZ2: 86 | JA2: 175 | JB2: 173 | JC2: 89 | JD2: 0 | JE2: 0 | JF2: 0 | JG2: 0 | JH2: 265 | JI2: 263 | JJ2: 0 | JK2: 0 | JL2: 263 | JM2: 87 | JN2: 259 | JO2: 0 | JP2: 351 | JQ2: 349 | JR2: 260 | JS2: 347 | JT2: 358 | JU2: 177 | JV2: 264 | JW2: 266 | JX2: 352 | JY2: 438 | JZ2: 0 | KA2: 343 | KB2: 0 | KC2: 958 | KD2: 0 | KE2: 0 | KF2: 1056 | KG2: 888 | KH2: 0 | KI2: 87 | KJ2: 630
A3: Hưng Yên | GX3: 86 | GY3: 89 | GZ3: 357 | HA3: 262 | HB3: 177 | HC3: 0 | HD3: 441 | HE3: 441 | HF3: 177 | HG3: 261 | HH3: 0 | HI3: 266 | HJ3: 179 | HK3: 0 | HL3: 0 | HM3: 255 | HN3: =88+88 -> 176 | HO3: 264 | HP3: 263 | HQ3: 268 | HR3: 265 | HS3: 262 | HT3: 0 | HU3: 84 | HV3: 261 | HW3: 346 | HX3: 258 | HY3: 266 | HZ3: 0 | IA3: 0 | IB3: 79 | IC3: 168 | ID3: 174 | IE3: 174 | IF3: 267 | IG3: 0 | IH3: 174 | II3: 261 | IJ3: 170 | IK3: 263 | IL3: 258 | IM3: 265 | IN3: 177 | IO3: 87 | IP3: 0 | IQ3: 0 | IR3: 171 | IS3: 263 | IT3: 263 | IU3: 89 | IV3: 265 | JA3: 175 | JH3: 87 | JJ3: 0 | JK3: 0
A4: Tp.HCM | IW4: 179 | IX4: 0 | IY4: 171 | IZ4: 86 | JB4: 173 | JC4: 89 | JD4: 0 | JE4: 0 | JF4: 0 | JG4: 0 | JH4: 178 | JI4: 263 | JJ4: 0 | JK4: 0 | JL4: 263 | JM4: 87 | JN4: 259 | JO4: 0 | JP4: 351 | JQ4: 349 | JR4: 260 | JS4: 347 | JT4: 358 | JU4: 177 | JV4: 264 | JW4: 266 | JX4: 352 | JY4: 438 | JZ4: 0 | KA4: 343 | KB4: 0 | KC4: 958 | KD4: 0 | KE4: 0 | KF4: 1056 | KG4: 888 | KH4: 0 | KI4: 87 | KJ4: 630
A5: Rerun | IH5: 57 | IR5: 75 | IT5: 49

Sheet Sum
A1: Mẻ | B1: No. of mtDNA profiles/ passed samples | C1: Rerun
A2: Tổng | B2: =SUM(B3:B6) -> 46185 | C2: =SUM(C3:C6) -> 2251
A3: 1-5 | B3: 40
A4: 6-14 | B4: 793
A5: 15-19 | B5: 385
A6: 20- | B6: ='From Batch 20'!Z2 -> 44967 | C6: ='From Batch 20'!Z3 -> 2251

Sheet Sum (From Batch 1)
A1: Tóm tắt XN mtDNA mẫu thân nhân*
A3: Mẻ | B3: Tổng mẫu TN | C3: Đã phân tích | D3: Đã chuyển KQ sang nhóm Science | E3: Đã xuất phiếu KQ | F3: Phiếu kết quả đã được chấp nhận | G3: Tình trạng | H3: *Không bao gồm 8 mẫu staff
A4: Tổng | B4: =B5+B7 -> 48436 | C4: =C5+C7 -> 48420 | D4: =D5+D7 -> 7919 | E4: =E5+E7 -> 95449 | F4: =F5+F7 -> 3287
A5: Tổng số mẫu 2024 (Từ batch 1 - 14) | B5: ='From Batch 6 to 14'!E2+40-8 -> 833 | C5: ='From Batch 6 to 14'!F2+40-8 -> 833 | D5: ='From Batch 6 to 14'!H2+40-8 -> 833 | E5: =SUM(E8:E9) -> 833 | F5: =SUM(F8:F9) -> 833
A6: Tổng đợt 2 (Mẻ 15 - 19) | B6: ='From Batch 15 to 19'!E2 -> 385 | C6: ='From Batch 15 to 19'!F2 -> 385 | D6: ='From Batch 15 to 19'!H2 -> 385 | E6: =E10 -> 385 | F6: =F10 -> 385 | G6: Xong hết
A7: Tổng số mẫu 2025 (Từ batch 15 - ) | B7: =SUM(B10:B1048576) -> 47603 | C7: =SUM(C10:C1048576) -> 47587 | D7: =SUM(D10:D1048576) -> 7086 | E7: =SUM(E10:E1048576) -> 94616 | F7: =SUM(F10:F1048576) -> 2454
A8: 1-5 | B8: 40 | C8: 40 | D8: 40 | E8: 40 | F8: 40
A9: 6-14 | B9: 793 | C9: 793 | D9: 793 | E9: 793 | F9: 793
A10: 15-19 | B10: ='From Batch 15 to 19'!E2 -> 385 | C10: ='From Batch 15 to 19'!F2 -> 385 | D10: ='From Batch 15 to 19'!H2 -> 385 | E10: =SUM('From Batch 15 to 19'!P4:P1048576) -> 385 | F10: =SUM('From Batch 15 to 19'!R4:R1048576) -> 385
A11: 20- | B11: ='From Batch 20'!C2 -> 47218 | C11: ='From Batch 20'!H2 -> 47202 | D11: ='From Batch 20'!O2 -> 6701 | E11: =SUM('From Batch 20'!V4:V1048576) -> 94231 | F11: =SUM('From Batch 20'!X4:X1048576) -> 2069

Sheet From Batch 15 to 19
A1: Batch mtDNA | B1: Lab Start Date | C1: Sequence Released Date | D1: Deadline for Report Submitted | E1: No. of Samples | F1: No. of Samples Analysed by Sequencher | G1: No. of Samples Passed by Sequencher Analysis | H1: No. of Samples Passed by Sequencher Analysis Transfered to Next Stage | I1: Sequencher Analysis Results from Lab to Sciences Date | J1: Sequencher Analysis (Batches) | K1: Analyst(s) | L1: Sequencher vs Pipeline Comparison | M1: Analyst(s) | N1: Regenerated Reports by the Science Team | O1: Regenerated Reports Realeased Date | P1: Numbers of Reports Released | Q1: Reports Check by Nam | R1: Final Reports | S1: Note1 | T1: Note2
A2: Sum of samples | B2: - | C2: - | D2: - | E2: =SUM(E4:E1048559) -> 385 | F2: =SUM(F4:F1048559) -> 385 | G2: =SUM(G4:G1048559) -> 385 | H2: =SUM(H4:H1048559) -> 385 | J2: =COUNTIF(J4:J1048576,"Done") -> 5 | K2: - | L2: - | M2: - | N2: - | Q2: - | R2: =SUM(R4:R8) -> 385
A3: Remaining samples | B3: - | C3: - | D3: - | F3: 0 | G3: 0 | H3: 0 | J3: - | K3: - | L3: - | M3: - | N3: - | Q3: - | R3: -
A4: 15 | C4: 250207 | E4: 92 | F4: 92 | G4: 92 | H4: 92 | I4: 250227 | J4: Done | K4: Nam (Ms) | L4: Done | M4: Cuc | N4: Released | O4: 250227 | P4: 92 | Q4: Done | R4: 92 | S4: 91/92 phiếu KQ đã đc released ngày 250212 và được Nam và a Tôn approved. 250329 lab đã chạy lại, phân tích xong và đã chuyển kq pt sequencher sang Science Team ngày 250227. Đã update report mới. --> Done
A5: 16 | C5: 250214 | E5: 92 | F5: 92 | G5: 92 | H5: 92 | I5: 250220 | J5: Done | K5: Nam (Ms) | N5: Released | O5: 250224 | P5: 92 | Q5: Done | R5: 92 | S5: 2 mẫu đã chạy bổ sung HVIF | T5: đã feeedback Cúc bổ sung thông tin đoạn phân tích ở 1 số phiếu KQ --> Done
A6: 17 | C6: 250220 | E6: 92 | F6: 92 | G6: 92 | H6: 92 | I6: 250224 | J6: Done | K6: Nam (Ms) | N6: Released | O6: 250224 | P6: 92 | Q6: Done | R6: 92 | S6: đã feeedback Cúc bổ sung thông tin đoạn phân tích ở 1 số phiếu KQ
A7: 18 | C7: 250221 | E7: 92 | F7: 92 | G7: 92 | H7: 92 | I7: 250226 | J7: Done | K7: Nam (Ms) | N7: Released | O7: 250226 | P7: 92 | Q7: Done | R7: 92
A8: 19 | C8: 250221 | E8: 17 | F8: 17 | G8: 17 | H8: 17 | I8: 250228 | J8: Done | K8: Nam (Ms) | N8: Released | O8: 250228 | P8: 17 | Q8: Done | R8: 17 | S8: lab chạy lại 250951 HV3F --> Nam pt Sequencher xong --> gửi KQ bổ sung ngày 250228

Sheet From Batch 6 to 14
A1: Batch mtDNA | B1: Lab Start Date | C1: Sequence Released Date | D1: Deadline for Report Submitted | E1: No. of Samples | F1: No. of Samples Analysed by Sequencher | G1: No. of Samples Passed by Sequencher Analysis | H1: No. of Samples Passed by Sequencher Analysis Transfered to the Sciene Team | I1: Sequencher Analysis Results from Lab to Sciences Date | J1: Sequencher Analysis (Batches) | K1: Analyst(s) | L1: Sequencher vs Pipeline Comparison | M1: Analyst(s) | N1: Regenerated Reports by the Science Team | O1: Regenerated Reports Realeased Date | P1: Numbers of Reports Released | Q1: Reports Check by Nam | R1: Final Reports | S1: Note
A2: Sum of samples | B2: - | C2: - | D2: - | E2: =SUM(E4:E1048576) -> 801 | F2: =SUM(F4:F1048576) -> 801 | G2: =SUM(G4:G1048576) -> 801 | H2: =SUM(H4:H1048576) -> 801 | J2: =COUNTIF(J4:J1048576,"Done") -> 10 | K2: - | L2: - | M2: - | N2: - | Q2: - | R2: =SUM(R9:R19) -> 793
A3: Remaining samples | B3: - | C3: - | D3: - | F3: =E2-F2 -> 0 | G3: =E2-G2 -> 0 | H3: =E2-H2 -> 0 | J3: - | K3: - | L3: - | M3: - | N3: - | Q3: - | R3: -
A4: 1 | B4: - | C4: - | D4: - | E4: - | J4: - | K4: - | L4: - | M4: - | N4: - | P4: - | R4: -
A5: 2 | B5: - | C5: - | D5: - | E5: - | J5: - | K5: - | L5: - | M5: - | N5: - | P5: - | R5: -
A6: 3 | B6: - | C6: - | D6: - | E6: - | J6: - | K6: - | L6: - | M6: - | N6: - | P6: - | R6: -
A7: 4 | B7: - | C7: - | D7: - | E7: - | J7: - | K7: - | L7: - | M7: - | N7: - | P7: - | R7: -
A8: 5 | B8: - | C8: - | D8: - | E8: - | J8: - | K8: - | L8: - | M8: - | N8: - | P8: - | R8: -
A9: 6 | E9: 94 | F9: 94 | G9: 94 | H9: 94 | J9: Done | K9: Nam (Ms) | L9: Done | M9: Nam (Ms) and Cuc | N9: Released | P9: 94 | Q9: Done | R9: 94
A10: 7 | E10: 94 | F10: 94 | G10: 94 | H10: 94 | J10: Done | K10: Nam (Ms) | L10: Done | M10: Nam (Ms) and Cuc | N10: Released | P10: 94 | Q10: Done | R10: 94
A11: 8 | E11: 94 | F11: 94 | G11: 94 | H11: 94 | J11: Done | K11: Nam (Ms) | N11: Released | O11: 250318 | P11: 94 | Q11: Done | R11: 94
A12: 9 | E12: 94 | F12: 94 | G12: 94 | H12: 94 | J12: Done | K12: Nam (Ms) | N12: Released | O12: 250321 | P12: 94 | Q12: Done | R12: 94 | S12: đã re-PCR-CR và reseq 4 mẫu 246373 HV1R, 246371 HV1F, 246387 HV1F, 246399 HV1F để confirm heteroplasmy
A13: 10_L1 | E13: 8 | F13: 8 | G13: 8 | H13: 8 | J13: x | K13: Nam (Ms) | N13: x | O13: x | P13: x | R13: x | S13: 8 staff samples
A14: 10_L2 | E14: 86 | F14: 86 | G14: 86 | H14: 86 | J14: Done | K14: Nam (Ms) | N14: Released | O14: 250321 | P14: 86 | Q14: Done | R14: 86 | S14: re-PCR-CR sau đó reseq 242763 HV2F: 121R? --> ko có hetero ở vị trí này
A15: 11 | E15: 94 | F15: 94 | G15: 94 | H15: 94 | J15: Done | K15: Nam (Ms) | L15: Done | M15: Cuc | N15: Released | P15: 94 | Q15: Done | R15: 94
A16: 12_L1 | E16: 5 | F16: 5 | G16: 5 | H16: 5 | J16: Done | K16: Nam (Ms) | L16: Done | M16: Cuc | N16: Released | P16: 5 | Q16: Done | R16: 5 | S16: 5 prioritized samples analysed
A17: 12_L2 | E17: 87 | F17: 87 | G17: 87 | H17: 87 | J17: Done | K17: Nam (Ms) | L17: Not yet started | N17: Released | O17: 250318 | P17: 87 | Q17: Done | R17: 87
A18: 13 | E18: 92 | F18: 92 | G18: 92 | H18: 92 | J18: Done | K18: Nam (Ms) | L18: Done | M18: Cuc | N18: Released | P18: 92 | Q18: Done | R18: 92
A19: 14 | E19: 53 | F19: 53 | G19: 53 | H19: 53 | J19: Done | K19: Nam (Ms) | L19: Done | M19: Cuc | N19: Released | P19: 53 | Q19: Done | R19: 53

Sheet Hung
A1: Đơn vị giải trình tự | B1: Batch | C1: Thời gian nhận | D1: Số mẫu nhận | E1: Mức độ ưu tiên | F1: Người phân tích | G1: Số mẫu đã phân tích | H1: Người kiểm tra 1 | I1: Người kiểm tra 2 | J1: Số mẫu trả kết quả | K1: Số mẫu chạy lại
A2: GST | B2: 20250530_mtDNA_73 | C2: =DATE(2025,6,4) -> 45812 | D2: 1 | E2: Không | G2: 1 | H2: N | I2: N | J2: 1 | K2: =G2-J2 -> 0
A3: GST | B3: 20250615_mtDNA_102 | C3: =DATE(2025,6,18) -> 45826 | D3: 1 | E3: Không | F3: H | G3: 1 | H3: N | I3: N | J3: 1 | K3: =G3-J3 -> 0
A4: GST | B4: MS_111125_001 | C4: =DATE(2025,11,12) -> 45973 | D4: 90 | E4: Không | F4: T | G4: 90 | H4: P | I4: N | J4: 89 | K4: =G4-J4 -> 1
A5: GST | B5: MS_181125_001 | C5: =DATE(2025,11,19) -> 45980 | D5: 90 | E5: Không | F5: X | G5: 90 | H5: P | I5: N | J5: 86 | K5: =G5-J5 -> 4
A6: GST | B6: MS_171125_002 | C6: 45980 | D6: 90 | E6: Không | F6: T | G6: 90 | H6: P | I6: N | J6: 89 | K6: =G6-J6 -> 1
A7: GST | B7: MS_191125_004 | C7: 45986 | D7: 90 | E7: Không | F7: Q | G7: 90 | H7: H | I7: N | J7: 90 | K7: =G7-J7 -> 0
A8: GST | B8: MS_191125_001 | C8: 45985 | D8: 90 | E8: Không | F8: HT | G8: 90 | H8: HT | I8: N | J8: 87 | K8: =G8-J8 -> 3
A9: GST | B9: MS_191125_002 | C9: 45985 | D9: 90 | E9: Không | F9: Q | G9: 90 | H9: P | I9: N | J9: 88 | K9: =G9-J9 -> 2
A10: GST | B10: MS_191125_003 | C10: 45986 | D10: 90 | E10: Không | F10: X | G10: 90 | H10: H | I10: N | J10: 90 | K10: =G10-J10 -> 0
A11: GST | B11: MS_211125_001 | C11: 45987 | D11: 90 | E11: Không | F11: X | G11: 90 | H11: H | I11: N | J11: 90 | K11: =G11-J11 -> 0
A12: GST | B12: MS_211125_002 | C12: 45989 | D12: 90 | E12: Không | F12: T | G12: 90 | H12: TH | I12: N | J12: 85 | K12: =G12-J12 -> 5
A13: GST | B13: MS_211125_003 | C13: 45989 | D13: 90 | E13: Không | F13: Q | G13: 90 | H13: P | I13: N | J13: 89 | K13: =G13-J13 -> 1
A14: GST | B14: MS_211125_004 | C14: 45989 | D14: 90 | E14: Không | F14: X | G14: 90 | H14: H | I14: N | J14: 89 | K14: =G14-J14 -> 1
A15: GST | B15: MS_211125_005 | C15: 45989 | D15: 90 | E15: Không | F15: H | G15: 90 | H15: H | I15: N | J15: 89 | K15: =G15-J15 -> 1
A16: GST | B16: MS_211125_006 | C16: 45991 | D16: 90 | E16: Không | F16: Q | G16: 90 | H16: P | I16: N | J16: 89 | K16: =G16-J16 -> 1
A17: GST | B17: MS_211125_007 | C17: 45991 | D17: 90 | E17: Không | F17: T | G17: 90 | H17: P | I17: N | J17: 88 | K17: =G17-J17 -> 2
... A114: GST | B114: MS_290126_003 | C114: 46059 | D114: 90 | E114: Không | F114: QX | G114: 90 | H114: P | I114: N | J114: 86 | K114: =G114-J114 -> 4
A115: GST | B115: MS_020226_002 | C115: 46060 | D115: 90 | E115: Không | F115: X | G115: 90 | H115: P
A116: GST | B116: MS_280126_003 | C116: 46062 | D116: 90 | E116: Không | F116: PQ | G116: 90 | H116: P
A117: GST | B117: MS_280126_002 | C117: 46062 | D117: 90 | E117: Không | F117: T | G117: 90 | H117: P
A119: CDI | E119: Bình thường
A120: PYQĐ | B120: 20250721_mtDNA_172 | C120: 45860 | D120: 30 | E120: Gấp | F120: TQ | G120: 30 | H120: N | I120: N | J120: 30 | K120: 0
A121: PYQĐ | B121: 20250718_mtDNA_163_L2 | C121: 45856 | D121: 5 | E121: Gấp | F121: H | G121: 5 | H121: N | I121: N | J121: 5 | K121: 0
A122: PYQĐ | B122: 20250717_mtDNA_163 | C122: 45856 | D122: 25 | E122: Gấp | F122: HP | G122: 25 | H122: N | I122: N | J122: 25 | K122: 0
A123: PYQĐ | B123: 20250731_mtDNA_190 | C123: 45870 | D123: 8 | E123: Gấp | F123: HT | G123: 8 | H123: N | I123: N | J123: 8 | K123: 0
A125: Viện CNSH

Sheet Sheet2
A1: Sequencher Analysis | B1: Analyst | C1: Sequencher vs Pipeline Comparison | D1: Analyst | E1: Regenerated Report | F1: Report Check | G1: Final Report
A2: Not yet started | B2: N (Ms) | C2: Not yet started | D2: N (Ms) | E2: Not yet released | F2: Not yet started | G2: Not yet started
A3: Processing | B3: H | C3: Processing | D3: H | E3: Released | F3: Processing | G3: Processing
A4: Done | B4: P | C4: Done | D4: P | E4: Processing | F4: Done | G4: Released
A5: Not perform | B5: Q | C5: Not perform | D5: Q | E5: x | F5: Not perform
A6: x | B6: T | D6: T
B7: R | D7: R
B8: X | D8: QR
B9: PQ | D9: HT
B10: HT | D10: HQ
B11: HQ | D11: PX
B12: PQR
B13: HR
B14: PR
B15: PT
B16: HP
B17: HTQ
B18: TQ
B19: HTP
B20: HPQT
B21: HPQTX
B22: XT
B23: HTX
... B28: QTX
